Workbook
Name BalanceForChart2: 'RE Calculations'!$F$23:INDEX('RE Calculations'!$F$23:$F$73,COUNT('RE Calculations'!$D$23:$D$73))
Name CoCForChart6: 'RE Calculations'!$J$136:INDEX('RE Calculations'!$J$136:$J$186,COUNT('RE Calculations'!$J$136:$J$186))
Name CostsForChart5: 'RE Calculations'!$E$136:INDEX('RE Calculations'!$E$136:$E$186,COUNT('RE Calculations'!$C$136:$C$186))
Name CumInterestForChart2: 'RE Calculations'!$E$23:INDEX('RE Calculations'!$E$23:$E$73,COUNT('RE Calculations'!$D$23:$D$73))
Name CumPrincipalForChart2: 'RE Calculations'!$D$23:INDEX('RE Calculations'!$D$23:$D$73,COUNT('RE Calculations'!$D$23:$D$73))
Name EqValueForChart3: 'RE Calculations'!$D$80:INDEX('RE Calculations'!$D$80:$D$130,COUNT('RE Calculations'!$C$80:$C$130))
Name GrossROIForChart4: 'RE Calculations'!$J$79:INDEX('RE Calculations'!$J$79:$J$130,COUNT('RE Calculations'!$H$79:$H$130))
Name HoldPeriodForChart1: 'RE Calculations'!$O$23:INDEX('RE Calculations'!$O$23:$O$73,COUNT('RE Calculations'!$L$23:$L$73))
Name HoldPeriodForChart2: 'RE Calculations'!$I$23:INDEX('RE Calculations'!$I$23:$I$73,COUNT('RE Calculations'!$D$23:$D$73))
Name HoldPeriodForChart3: 'RE Calculations'!$E$80:INDEX('RE Calculations'!$E$80:$E$130,COUNT('RE Calculations'!$C$80:$C$130))
Name HoldPeriodForChart4: 'RE Calculations'!$L$79:INDEX('RE Calculations'!$L$79:$L$130,COUNT('RE Calculations'!$H$79:$H$130))
Name HoldPeriodForChart5: 'RE Calculations'!$G$136:INDEX('RE Calculations'!$G$136:$G$186,COUNT('RE Calculations'!$C$136:$C$186))
Name HoldPeriodForChart6: 'RE Calculations'!$M$136:INDEX('RE Calculations'!$M$136:$M$186,COUNT('RE Calculations'!$J$136:$J$186))
Name InterestForChart1: 'RE Calculations'!$M$23:INDEX('RE Calculations'!$M$23:$M$73,COUNT('RE Calculations'!$L$23:$L$73))
Name LoanForChart5: 'RE Calculations'!$F$136:INDEX('RE Calculations'!$F$136:$F$186,COUNT('RE Calculations'!$C$136:$C$186))
Name NetROIForChart4: 'RE Calculations'!$K$79:INDEX('RE Calculations'!$K$79:$K$130,COUNT('RE Calculations'!$H$79:$H$130))
Name PrincipalForChart1: 'RE Calculations'!$L$23:INDEX('RE Calculations'!$L$23:$L$73,COUNT('RE Calculations'!$L$23:$L$73))
Name PropValueForChart3: 'RE Calculations'!$C$80:INDEX('RE Calculations'!$C$80:$C$130,COUNT('RE Calculations'!$C$80:$C$130))
Name RentForChart5: 'RE Calculations'!$C$136:INDEX('RE Calculations'!$C$136:$C$186,COUNT('RE Calculations'!$C$136:$C$186))
Name YearForChart1: 'RE Calculations'!$K$23:INDEX('RE Calculations'!$K$23:$K$73,COUNT('RE Calculations'!$L$23:$L$73))
Name YearForChart3: 'RE Calculations'!$B$80:INDEX('RE Calculations'!$B$80:$B$130,COUNT('RE Calculations'!$C$80:$C$130))
Name YearForChart4: 'RE Calculations'!$G$79:INDEX('RE Calculations'!$G$79:$G$130,COUNT('RE Calculations'!$H$79:$H$130))
Name YearForChart5: 'RE Calculations'!$B$136:INDEX('RE Calculations'!$B$136:$B$186,COUNT('RE Calculations'!$C$136:$C$186))
Name YearForChart6: 'RE Calculations'!$I$136:INDEX('RE Calculations'!$I$136:$I$186,COUNT('RE Calculations'!$J$136:$J$186))
Name YieldCostForChart6: 'RE Calculations'!$K$136:INDEX('RE Calculations'!$K$136:$K$186,COUNT('RE Calculations'!$J$136:$J$186))
Name YieldValueForChart6: 'RE Calculations'!$L$136:INDEX('RE Calculations'!$L$136:$L$186,COUNT('RE Calculations'!$J$136:$J$186))

Sheet Intro
B2: Investment Tool
B3: If you have questions or need consultation feel free to reach out on whatsapp +971 52 8602947
B4: This is a tool that I crafted to streamline the assessment and analysis of real estate investments
B5: It evaluates key factors like rental revenue, property value appreciation, and expenses related to buying, maintaining, and selling, helping you gauge the viability and returns of a potential investment.
B6: The workbook comes equipped with essential features such as a detailed analysis overview, mortgage calculation tools, financial projection models, and a section for researching comparable properties.
B7: this versatile tool can also be easily tailored to assess Airbnb rental opportunities.
B9: Important Note: The cells are unlocked for flexibility, so please input or modify data only in the cells highlighted in LIGHT BROWN
B10: You’ll find links to the relevant spreadsheet in the table below for easy access:
B12: No. | C12: Sheet Name | D12: Description
B13: 1 | C13: Inputs | D13: Enter the primary inputs and assumptions on this sheet, and they will automatically populate throughout the entire workbook. It also features a concise summary table, providing a clear, at-a-glance view of how adjustments to the assumptions impact the overall deal.
B14: 2 | C14: Analysis Summary | D14: Easy-to-print dashboards that showcase essential metrics and insightful charts, helping you clearly visualize the investment opportunity. Switch effortlessly between a Principal & Interest Loan and an Interest Only Loan with a simple toggle.
B15: 3 | C15: Mortgage Calculators (By Month) | D15: Features a detailed Amortization Schedule for both Principal & Interest and Interest Only Loans, calculated on a monthly basis. Additionally, it offers a mortgage comparison tool to easily evaluate two different financing scenarios side by side.
B16: 4 | C16: Mortgage Calculators (By Year) | D16: Features a detailed Amortization Schedule for both Principal & Interest and Interest Only Loans, calculated on a Yearly basis. Additionally, it offers a mortgage comparison tool to easily evaluate two different financing scenarios side by side.
B17: 5 | C17: Forecast (By Month) | D17: Monthly forecast of the investment’s performance, factoring in rental revenue, property value appreciation, and expenses related to buying, maintaining, and selling throughout the mortgage term. It incorporates cash flows, as well as gross and net profits for a complete financial overview.
B18: 6 | C18: Forecast (By Year) | D18: Yearly forecast of the investment’s performance, factoring in rental revenue, property value appreciation, and expenses related to buying, maintaining, and selling throughout the mortgage term. It incorporates cash flows, as well as gross and net profits for a complete financial overview.
B19: 7 | C19: Comparables | D19: User-friendly tool designed to evaluate comparable properties, both currently listed and recently sold, within the surrounding area. It also provides rental price comparisons for a well-rounded analysis.
B20: 8 | C20: Notes | D20: For any notes
B23: If you have any questions or feedback, please do not hesitate to message me on whatsapp +971 52 860 2947
B24: I also provide help with analysing any of your investment and provide consultation on wether a property is a worthwile investment, feel free to reach out anytime!

Sheet Inputs
B1: *** NOTE: INSERT/EDIT DATA IN LIGHT BROWN CELLS ONLY ***
B3: KEY INFORMATION | J3: QUICK SUMMARY
C4: Value | D4: Input Type | E4: Active? | G4: Notes/Comments | J4: Key Information
B5: Address | C5: The Lofts | G5: Input address for Analysis Summary tab | J5: Total Purchase Price | K5: =C6 -> 1499950
B6: Total Purchase Price | C6: 1499950 | J6: Down Payment (%) | K6: =IF($E7="YES",$C7,$C8/$C$6) -> 1
B7: Down Payment | C7: 1 | D7: % of Total Price | E7: YES | J7: Down Payment ($) | K7: =IF($E7="YES",$C7*$C$6,$C8) -> 1499950
C8: 80000 | D8: $ Value | E8: =IF($E$7="YES","NO","YES") -> NO | J8: Principal Amount | K8: =K5-K7 -> 0
B9: Yr 1 Market Value / After Repair Value (ARV) | C9: 1635000 | G9: Used to calculate total appreciation and profit | J9: Yr 1 Market Value / After Repair Value (ARV) | K9: =C9 -> 1635000
B10: Holding Period (Years) | C10: 5 | G10: Set to maximum loan duration if no intention to sell | J10: Holding Period | K10: =$C$10 -> 5
B11: Appreciation (Annual) | C11: 0.05 | J11: Appreciation (Annual) | K11: =C11 -> 0.05
B12: Rental Income | C12: 103000 | D12: per annum | J12: Monthly Appreciation | K12: =POWER((1+K11),1/12)-1 -> 0.0040741238
B13: Other Income | C13: 0 | D13: per week | J13: Estimated Selling Price | K13: =$K$9*(1+$K$11)^$K$10 -> 2086720.4
B14: Rental Growth (Annual) | C14: 0.05 | J14: Rental Income | K14: =TEXT($C$12,"AED#,##0.00")&" "&$D$12 -> AED103,000.00 per annum
J15: Other Income | K15: =TEXT($C$13,"AED#,##0.00")&" "&$D$13 -> AED0.00 per week
J16: Equivalent Monthly Income | K16: =($C$12*_xlfn.XLOOKUP($D$12,'RE Calculations'!$B$12:$B$16,'RE Calculations'!$C$12:$C$16,"Error - check formula",0)+$C$13*_xlfn.XLOOKUP($D$13,'RE Calculations'!$B$12:$B$16,'RE Calculations'!$C$12:$C$16,"Error - check formula",0))/12 -> 8583.3333
B17: MORTGAGE INFORMATION | J17: Rental Growth (Annual) | K17: =C14 -> 0.05
B18: Principal & Interest Loan (P&I) | J18: Purchasing Costs Required (Incl. Down Payment) | K18: =F56 -> 1601027
B19: Annual Interest Rate | C19: 0.045 | G19: Nominal Interest Rate | J19: Selling Costs | K19: =F95 -> 46234.407
B20: Loan Duration (Years) | C20: 30 | G20: Input the loan duration
B21: Fees | C21: 100 | D21: per annum | G21: Additional fees including for offset/redraw accounts | J21: Simple Cash Flow Calculator | K21: per month
J22: Total Income (Rent + Other) | K22: =K16*12/_xlfn.XLOOKUP($K$21,'RE Calculations'!$B$12:$B$16,'RE Calculations'!$C$12:$C$16,"Error - Check Unit Input",0) -> 8583.3333
B23: Interest Only Loan (IO) | J23: Ongoing Fees/Costs | K23: =F79/_xlfn.XLOOKUP($K$21,'RE Calculations'!$B$12:$B$16,'RE Calculations'!$C$12:$C$16,"Error - Check Unit Input",0) -> 2432.3333
B24: Annual Interest Rate | C24: 0.0475 | G24: Nominal Interest Rate | J24: Loan Payment (P&I Loan) | K24: =K39*12/_xlfn.XLOOKUP($K$21,'RE Calculations'!$B$12:$B$16,'RE Calculations'!$C$12:$C$16,"Error - Check Unit Input",0) -> 100
B25: Interest Only Duration (Years) | C25: 5 | G25: Loan switches to a typical Principal and Interest Loan after this duration | J25: Total Cash Flow (P&I Loan) | K25: =K22-K23-K24 -> 6051
B26: Standard Interest Rate (after IO period) | C26: 0.045 | G26: Nominal Interest Rate | J26: Cash-on-Cash Return (P&I Loan) | K26: =(K25*_xlfn.XLOOKUP($K$21,'RE Calculations'!$B$12:$B$16,'RE Calculations'!$C$12:$C$16,"Error - Check Unit Input",0))/K18 -> 0.045353389
B27: Total Loan Duration (Years) | C27: 30 | G27: Maximum 50 years | J27: Loan Payment (IO Loan) | K27: =K49*12/_xlfn.XLOOKUP($K$21,'RE Calculations'!$B$12:$B$16,'RE Calculations'!$C$12:$C$16,"Error - Check Unit Input",0) -> 120
B28: Fees | C28: 120 | D28: per annum | G28: Additional fees including for offset/redraw accounts | J28: ="Loan Payment After "&K44&" Years (IO Loan)" -> Loan Payment After 5 Years (IO Loan) | K28: =K50*12/_xlfn.XLOOKUP($K$21,'RE Calculations'!$B$12:$B$16,'RE Calculations'!$C$12:$C$16,"Error - Check Unit Input",0) -> 120
J29: Total Cash Flow (IO Loan) | K29: =K22-K23-K27 -> 6031
J30: ="Total Cash Flow After "&K44&" Years (IO Loan)" -> Total Cash Flow After 5 Years (IO Loan) | K30: =K22-K23-K28 -> 6031
B31: PURCHASING COSTS | J31: Cash-on-Cash Return (IO Loan) | K31: =(K29*_xlfn.XLOOKUP($K$21,'RE Calculations'!$B$12:$B$16,'RE Calculations'!$C$12:$C$16,"Error - Check Unit Input",0))/K18 -> 0.045203485
B32: Item | C32: % of Purchase Price | D32: One Time Cost | E32: Tax Deductible? | F32: Lump Sum Equivalent | G32: Notes/Comments
B33: Legal fees | C33: 0 | D33: 0 | E33: FALSE | F33: =IFERROR(IF(OR(C33=0,C33="",ISERROR(C33)),D33,C33*$C$6),"Error - Check Input") -> 0 | G33: Alternatively, get a Defect & Handover inspection for new builds | J33: Mortgage Information
B34: Conveyancer/Solicitor Fees | C34: 0 | D34: 4500 | E34: FALSE | F34: =IFERROR(IF(OR(C34=0,C34="",ISERROR(C34)),D34,C34*$C$6),"Error - Check Input") -> 4500 | G34: Make sure to confirm prices, extra charges and scope of services with conveyancer | J34: Principal & Interest Loan (P&I)
B35: Strata Report | C35: 0 | D35: 0 | E35: FALSE | F35: =IFERROR(IF(OR(C35=0,C35="",ISERROR(C35)),D35,C35*$C$6),"Error - Check Input") -> 0 | G35: Look for info on fees, special levies, find balance, future building works/maintenance plans | J35: Annual Interest Rate | K35: =C19 -> 0.045
B36: Mortgage registration fee 0.25% | C36: 0 | D36: 0 | E36: FALSE | F36: =IFERROR(IF(OR(C36=0,C36="",ISERROR(C36)),D36,C36*$C$6),"Error - Check Input") -> 0 | G36: Includes Loan Application + Establishment Fees, Documentation + Prep Fees | J36: Equivalent Monthly Interest Rate | K36: =K35/12 -> 0.00375
B37: Mortgage Insurance | C37: 0 | D37: 0 | E37: FALSE | F37: =IFERROR(IF(OR(C37=0,C37="",ISERROR(C37)),D37,C37*$C$6),"Error - Check Input") -> 0 | G37: Varies depending on LVR and total loan amount | J37: Loan Duration (Years) | K37: =C20 -> 30
B38: Valuation/Appraisal Fees | C38: 0 | D38: 0 | E38: FALSE | F38: =IFERROR(IF(OR(C38=0,C38="",ISERROR(C38)),D38,C38*$C$6),"Error - Check Input") -> 0 | G38: Input valuation fee if you paid for one | J38: Fees | K38: =TEXT($C$21,"AED#,##0.00")&" "&$D$21 -> AED100.00 per annum
B39: 4% Dubai Land department | C39: 0.04 | D39: 700 | E39: FALSE | F39: =IFERROR(IF(OR(C39=0,C39="",ISERROR(C39)),D39,C39*$C$6),"Error - Check Input") -> 59998 | G39: Registration of Discharge, Registration and Transfers | J39: Monthly Loan Payment | K39: =-PMT(K36,K37*12,K8)+$C$21*_xlfn.XLOOKUP($D$21,'RE Calculations'!$B$12:$B$16,'RE Calculations'!$C$12:$C$16,"ERROR - Check Input") -> 100
B40: NOC | C40: 0 | D40: 2000 | E40: FALSE | F40: =IFERROR(IF(OR(C40=0,C40="",ISERROR(C40)),D40,C40*$C$6),"Error - Check Input") -> 2000 | G40: NOC Paid to the developer
B41: Utilities and Services (Connection Fee) | C41: 0 | D41: 0 | E41: FALSE | F41: =IFERROR(IF(OR(C41=0,C41="",ISERROR(C41)),D41,C41*$C$6),"Error - Check Input") -> 0 | G41: Depends on whether property requires new connection | J41: Interest Only Loan (IO)
...

Sheet Analysis Summary
B2: Principal & Interest Loan (P&I) | C2: <-- Toggle between Principal & Interest Loan and Interest Only Loan
B4: =Inputs!$C$5 -> The Lofts | Z4: =Inputs!$C$5 -> The Lofts | BK4: =Inputs!$C$5 -> The Lofts
B6: KEY INFORMATION | E6: =$B$2 -> Principal & Interest Loan (P&I) | Z6: ="With a holding period of "&$C$12&" years:" -> With a holding period of 5 years: | AM6: =$B$2 -> Principal & Interest Loan (P&I) | BK6: Year 1 | CE6: ="Year "&Inputs!$K$10&" (Holding Period)" -> Year 5 (Holding Period)
B7: Total Price | C7: =Inputs!$K5 -> 1499950 | Z7: Purchasing Costs | AF7: Estimated Property Value
B8: Down Payment (%) | C8: =Inputs!$K6 -> 1 | BK8: Total Rental Income | BX8: =IF('Analysis Summary'!$B$2=Inputs!$B$18,_xlfn.XLOOKUP(1,'Forecast (By Year)'!$F$3:$F$55,'Forecast (By Year)'!$I$3:$I$55),_xlfn.XLOOKUP(1,'Forecast (By Year)'!$AD$3:$AD$55,'Forecast (By Year)'!$AG$3:$AG$55)) -> 103000 | CE8: Total Rental Income | CR8: =IF('Analysis Summary'!$B$2=Inputs!$B$18,_xlfn.XLOOKUP(Inputs!$K$10,'Forecast (By Year)'!$F$3:$F$55,'Forecast (By Year)'!$I$3:$I$55),_xlfn.XLOOKUP(Inputs!$K$10,'Forecast (By Year)'!$AD$3:$AD$55,'Forecast (By Year)'!$AG$3:$AG$55)) -> 125197.14
B9: Down Payment ($) | C9: =Inputs!$K7 -> 1499950 | BK9: Total Ongoing Fees/Costs | BX9: =IF('Analysis Summary'!$B$2=Inputs!$B$18,_xlfn.XLOOKUP(1,'Forecast (By Year)'!$F$3:$F$55,'Forecast (By Year)'!$L$3:$L$55),_xlfn.XLOOKUP(1,'Forecast (By Year)'!$AD$3:$AD$55,'Forecast (By Year)'!$AJ$3:$AJ$55)) -> 29188 | CE9: Total Ongoing Fees/Costs | CR9: =IF('Analysis Summary'!$B$2=Inputs!$B$18,_xlfn.XLOOKUP(Inputs!$K$10,'Forecast (By Year)'!$F$3:$F$55,'Forecast (By Year)'!$L$3:$L$55),_xlfn.XLOOKUP(Inputs!$K$10,'Forecast (By Year)'!$AD$3:$AD$55,'Forecast (By Year)'!$AJ$3:$AJ$55)) -> 31629.686
B10: Principal Amount | C10: =Inputs!$K8 -> 0 | Z10: ='RE Calculations'!H194 -> 1601027 | AF10: ='RE Calculations'!H195 -> 2086720.4 | BK10: ="Loan Repayment - "&$B$2 -> Loan Repayment - Principal & Interest Loan (P&I) | BX10: =IF('Analysis Summary'!$B$2=Inputs!$B$18,_xlfn.XLOOKUP(1,'Forecast (By Year)'!$F$3:$F$55,'Forecast (By Year)'!$M$3:$M$55),_xlfn.XLOOKUP(1,'Forecast (By Year)'!$AD$3:$AD$55,'Forecast (By Year)'!$AK$3:$AK$55)) -> 0 | CE10: ="Loan Repayment - "&$B$2 -> Loan Repayment - Principal & Interest Loan (P&I) | CR10: =IF('Analysis Summary'!$B$2=Inputs!$B$18,_xlfn.XLOOKUP(Inputs!$K$10,'Forecast (By Year)'!$F$3:$F$55,'Forecast (By Year)'!$M$3:$M$55),_xlfn.XLOOKUP(Inputs!$K$10,'Forecast (By Year)'!$AD$3:$AD$55,'Forecast (By Year)'!$AK$3:$AK$55)) -> 0
B11: Yr 1 Market Value / After Repair Value (ARV) | C11: =Inputs!$K9 -> 1635000 | BK11: Before Tax Cash Flow | BX11: =BX8-BX9-BX10 -> 73812 | CE11: Before Tax Cash Flow | CR11: =CR8-CR9-CR10 -> 93567.458
B12: Holding Period | C12: =Inputs!$K10 -> 5
B13: Appreciation (Annual) | C13: =Inputs!$K11 -> 0.05 | Z13: Cumulative Cash Flow | AF13: Estimated Equity Value | BK13: Total Ongoing Fees/Costs | BX13: =BX9 -> 29188 | CE13: Total Ongoing Fees/Costs | CR13: =CR9 -> 31629.686
B14: Monthly Appreciation | C14: =Inputs!$K12 -> 0.0040741238 | BK14: Interest + Fees | BX14: =IF('Analysis Summary'!$B$2=Inputs!$B$18,_xlfn.XLOOKUP(1,'Forecast (By Year)'!$F$3:$F$55,'Forecast (By Year)'!$O$3:$O$55),_xlfn.XLOOKUP(1,'Forecast (By Year)'!$AD$3:$AD$55,'Forecast (By Year)'!$AM$3:$AM$55)) -> 100 | CE14: Interest + Fees | CR14: =IF('Analysis Summary'!$B$2=Inputs!$B$18,_xlfn.XLOOKUP(Inputs!$K$10,'Forecast (By Year)'!$F$3:$F$55,'Forecast (By Year)'!$O$3:$O$55),_xlfn.XLOOKUP(Inputs!$K$10,'Forecast (By Year)'!$AD$3:$AD$55,'Forecast (By Year)'!$AM$3:$AM$55)) -> 100
B15: Estimated Selling Price | C15: =Inputs!$K13 -> 2086720.4 | BK15: Depreciation | BX15: =IF('Analysis Summary'!$B$2=Inputs!$B$18,_xlfn.XLOOKUP(1,'Forecast (By Year)'!$F$3:$F$55,'Forecast (By Year)'!$P$3:$P$55),_xlfn.XLOOKUP(1,'Forecast (By Year)'!$AD$3:$AD$55,'Forecast (By Year)'!$AN$3:$AN$55)) -> 0 | CE15: Depreciation | CR15: =IF('Analysis Summary'!$B$2=Inputs!$B$18,_xlfn.XLOOKUP(Inputs!$K$10,'Forecast (By Year)'!$F$3:$F$55,'Forecast (By Year)'!$P$3:$P$55),_xlfn.XLOOKUP(Inputs!$K$10,'Forecast (By Year)'!$AD$3:$AD$55,'Forecast (By Year)'!$AN$3:$AN$55)) -> 0
B16: Rental Income | C16: =Inputs!$K14 -> AED103,000.00 per annum | Z16: ='RE Calculations'!H196 -> 417244.62 | AF16: ='RE Calculations'!H197 -> 2086720.4 | BK16: Total Deductions | BX16: =SUM(BX13:CB15) -> 29288 | CE16: Total Deductions | CR16: =SUM(CR13:CV15) -> 31729.686
B17: Other Income | C17: =Inputs!$K15 -> AED0.00 per week
B18: Equivalent Monthly Income | C18: =Inputs!$K16 -> 8583.3333 | BK18: ="Tax Payment / Credit (at "&Inputs!$K$54*100&"% tax rate)" -> Tax Payment / Credit (at 0% tax rate) | BX18: =IF('Analysis Summary'!$B$2=Inputs!$B$18,_xlfn.XLOOKUP(1,'Forecast (By Year)'!$F$3:$F$55,'Forecast (By Year)'!$S$3:$S$55),_xlfn.XLOOKUP(1,'Forecast (By Year)'!$AD$3:$AD$55,'Forecast (By Year)'!$AQ$3:$AQ$55)) -> 0 | CE18: ="Tax Payment / Credit (at "&Inputs!$K$54*100&"% tax rate)" -> Tax Payment / Credit (at 0% tax rate) | CR18: =IF('Analysis Summary'!$B$2=Inputs!$B$18,_xlfn.XLOOKUP(Inputs!$K$10,'Forecast (By Year)'!$F$3:$F$55,'Forecast (By Year)'!$S$3:$S$55),_xlfn.XLOOKUP(Inputs!$K$10,'Forecast (By Year)'!$AD$3:$AD$55,'Forecast (By Year)'!$AQ$3:$AQ$55)) -> 0
B19: Rental Growth (Annual) | C19: =Inputs!$K17 -> 0.05 | Z19: Gross Profit After Sale (excl. Cash Flow) | AF19: Net Profit After Sale (incl. Cash Flow) | BK19: After Tax Cash Flow | BX19: =BX11-BX18 -> 73812 | CE19: After Tax Cash Flow | CR19: =CR11-CR18 -> 93567.458
B20: Purchasing Costs Required (Incl. Down Payment) | C20: =Inputs!$K18 -> 1601027
B21: Selling Costs | C21: =Inputs!$K19 -> 46234.407 | BS21: Before Tax | CM21: Before Tax
Z22: ='RE Calculations'!H198 -> 439458.95 | AF22: ='RE Calculations'!H199 -> 856703.56 | BK22: Cash-on-Cash Return | BQ22: Yield on Cost | BW22: Yield on Value | CE22: Cash-on-Cash Return | CK22: Yield on Cost | CQ22: Yield on Value
B23: MORTGAGE INFORMATION
B24: Principal & Interest Loan (P&I) | BK24: ='RE Calculations'!H210 -> 0.046102908 | BQ24: ='RE Calculations'!H211 -> 0.04920964 | BW24: ='RE Calculations'!H212 -> 0.045144954 | CE24: ='RE Calculations'!H218 -> 0.058442149 | CK24: ='RE Calculations'!H219 -> 0.062380385 | CQ24: ='RE Calculations'!H220 -> 0.057227803
B25: Annual Interest Rate | C25: =Inputs!K35 -> 0.045 | Z25: Gross Annualized Return-on-Investment | AF25: Net Annualized Return-on-Investment
B26: Equivalent Monthly Interest Rate | C26: =Inputs!K36 -> 0.00375 | BS26: After Tax | CM26: After Tax
B27: Loan Duration | C27: =Inputs!K37 -> 30 | BK27: Cash-on-Cash Return | BQ27: Yield on Cost | BW27: Yield on Value | CE27: Cash-on-Cash Return | CK27: Yield on Cost | CQ27: Yield on Value
B28: Fees | C28: =Inputs!K38 -> AED100.00 per annum | Z28: ='RE Calculations'!H200 -> 0.054897131 | AF28: ='RE Calculations'!H201 -> 0.10701925
B29: Monthly Loan Payment | C29: =Inputs!K39 -> 100 | BK29: ='RE Calculations'!H214 -> 0.046102908 | BQ29: ='RE Calculations'!H215 -> 0.04920964 | BW29: ='RE Calculations'!H216 -> 0.045144954 | CE29: ='RE Calculations'!H222 -> 0.058442149 | CK29: ='RE Calculations'!H223 -> 0.062380385 | CQ29: ='RE Calculations'!H224 -> 0.057227803
B31: Interest Only Loan (IO) | Z31: Gross Annualized Return-on-Equity | AF31: Net Annualized Return-on-Equity
B32: Annual Interest Rate | C32: =Inputs!K42 -> 0.0475 | BK32: =$B$2 -> Principal & Interest Loan (P&I)
B33: Equivalent Monthly Interest Rate | C33: =Inputs!K43 -> 0.0039583333
B34: Interest Only Duration | C34: =Inputs!K44 -> 5 | Z34: ='RE Calculations'!H202 -> 0.042119582 | AF34: ='RE Calculations'!H203 -> 0.08211005
B35: Standard Interest Rate (after interest only period) | C35: =Inputs!K45 -> 0.045
B36: Equivalent Monthly Interest Rate | C36: =Inputs!K46 -> 0.00375
B37: Total Loan Duration | C37: =Inputs!K47 -> 30 | Z37: Capitalization Rate | AF37: Debt Service Coverage Ratio
B38: Fees | C38: =Inputs!K48 -> AED120.00 per annum
B39: Monthly Loan Payment (First 5 Years) | C39: =Inputs!K49 -> 120
B40: After Interest Only Period | C40: =Inputs!K50 -> 120 | Z40: ='RE Calculations'!H204 -> 0.044839481 | AF40: ='RE Calculations'!H205 -> 1251.9714
B42: FORECAST ASSUMPTIONS | E42: ="With a holding period of "&$C$12&" years:" -> With a holding period of 5 years:
B43: Inflation (Annual) | C43: =Inputs!K53 -> 0 | E43: Annual Payment | H43: Loan Balance | M43: Cumulative Principal | S43: Cumulative Interest + Fees | Z43: Loan To Value Ratio | AF43: Loan To Cost Ratio
B44: Tax Bracket | C44: =Inputs!K54 -> 0
B45: Value Eligible for Depreciation (%) | C45: =Inputs!K55 -> 0
...

Sheet RE Calculations
B1: *** NOTE: THIS SHEET CONTAINS SOME KEY CALCULATIONS BEHIND THE WORKBOOK. PLEASE DO NOT EDIT OR SOME FORMULAS/CHARTS WILL BE BROKEN. ***
B3: TOTAL INCOME
B4: per week | C4: =(Inputs!$C$12*_xlfn.XLOOKUP(Inputs!$D$12,'RE Calculations'!$B$12:$B$16,'RE Calculations'!$C$12:$C$16,"Error - Check Unit Input",0)+Inputs!$C$13*_xlfn.XLOOKUP(Inputs!$D$13,'RE Calculations'!$B$12:$B$16,'RE Calculations'!$C$12:$C$16,"Error - Check Unit Input",0))/_xlfn.XLOOKUP(B4,'RE Calculations'!$B$12:$B$16,'RE Calculations'!$C$12:$C$16,"Error - Check Unit Input",0) -> 1980.7692
B5: per fortnight | C5: =(Inputs!$C$12*_xlfn.XLOOKUP(Inputs!$D$12,'RE Calculations'!$B$12:$B$16,'RE Calculations'!$C$12:$C$16,"Error - Check Unit Input",0)+Inputs!$C$13*_xlfn.XLOOKUP(Inputs!$D$13,'RE Calculations'!$B$12:$B$16,'RE Calculations'!$C$12:$C$16,"Error - Check Unit Input",0))/_xlfn.XLOOKUP(B5,'RE Calculations'!$B$12:$B$16,'RE Calculations'!$C$12:$C$16,"Error - Check Unit Input",0) -> 3961.5385
B6: per month | C6: =(Inputs!$C$12*_xlfn.XLOOKUP(Inputs!$D$12,'RE Calculations'!$B$12:$B$16,'RE Calculations'!$C$12:$C$16,"Error - Check Unit Input",0)+Inputs!$C$13*_xlfn.XLOOKUP(Inputs!$D$13,'RE Calculations'!$B$12:$B$16,'RE Calculations'!$C$12:$C$16,"Error - Check Unit Input",0))/_xlfn.XLOOKUP(B6,'RE Calculations'!$B$12:$B$16,'RE Calculations'!$C$12:$C$16,"Error - Check Unit Input",0) -> 8583.3333
B7: per quarter | C7: =(Inputs!$C$12*_xlfn.XLOOKUP(Inputs!$D$12,'RE Calculations'!$B$12:$B$16,'RE Calculations'!$C$12:$C$16,"Error - Check Unit Input",0)+Inputs!$C$13*_xlfn.XLOOKUP(Inputs!$D$13,'RE Calculations'!$B$12:$B$16,'RE Calculations'!$C$12:$C$16,"Error - Check Unit Input",0))/_xlfn.XLOOKUP(B7,'RE Calculations'!$B$12:$B$16,'RE Calculations'!$C$12:$C$16,"Error - Check Unit Input",0) -> 25750
B8: per annum | C8: =(Inputs!$C$12*_xlfn.XLOOKUP(Inputs!$D$12,'RE Calculations'!$B$12:$B$16,'RE Calculations'!$C$12:$C$16,"Error - Check Unit Input",0)+Inputs!$C$13*_xlfn.XLOOKUP(Inputs!$D$13,'RE Calculations'!$B$12:$B$16,'RE Calculations'!$C$12:$C$16,"Error - Check Unit Input",0))/_xlfn.XLOOKUP(B8,'RE Calculations'!$B$12:$B$16,'RE Calculations'!$C$12:$C$16,"Error - Check Unit Input",0) -> 103000
B10: PERIOD CONVERTER
B11: Units (Period) | C11: Annual Equivalent
B12: per week | C12: 52
B13: per fortnight | C13: 26
B14: per month | C14: 12
B15: per quarter | C15: 4
B16: per annum | C16: 1
B18: CHARTS FOR ANALYSIS SUMMARY TAB
B19: Loan Amortization Chart | K19: Annual Payments
B20: ='Analysis Summary'!$E$6 -> Principal & Interest Loan (P&I) | I20: =_xlfn.MAXIFS(D22:E73,D22:E73,">0") -> 3000 | K20: ='Analysis Summary'!$E$6 -> Principal & Interest Loan (P&I) | O20: =_xlfn.XLOOKUP(Inputs!$K$10,'RE Calculations'!$K$22:$K$73,'RE Calculations'!$N$22:$N$73) -> 100
B21: Year | C21: Cumulative Payment | D21: Cumulative Principal | E21: Cumulative Interest + Fees | F21: Balance | G21: Principal Label | H21: Interest + Fees Label | I21: Holding Period | K21: Year | L21: Principal | M21: Interest + Fees | N21: Sum | O21: Holding Period
B22: 0 | C22: =IF($B$20=Inputs!$B$18,IF($B22<='Mortgage Calculators (By Year)'!$C$9,SUM('Mortgage Calculators (By Year)'!C$22:C22),NA()),IF($B22<='Mortgage Calculators (By Year)'!$J$12,SUM('Mortgage Calculators (By Year)'!J$22:J22),NA())) -> 0 | D22: =IF($B$20=Inputs!$B$18,IF($B22<='Mortgage Calculators (By Year)'!$C$9,SUM('Mortgage Calculators (By Year)'!D$22:D22),NA()),IF($B22<='Mortgage Calculators (By Year)'!$J$12,SUM('Mortgage Calculators (By Year)'!K$22:K22),NA())) -> 0 | E22: =IF($B$20=Inputs!$B$18,IF($B22<='Mortgage Calculators (By Year)'!$C$9,SUM('Mortgage Calculators (By Year)'!E$22:E22),NA()),IF($B22<='Mortgage Calculators (By Year)'!$J$12,SUM('Mortgage Calculators (By Year)'!L$22:L22),NA())) -> 0 | F22: =IF($B$20=Inputs!$B$18,IF($B22<='Mortgage Calculators (By Year)'!$C$9,'Mortgage Calculators (By Year)'!F22,NA()),IF($B22<='Mortgage Calculators (By Year)'!$J$12,'Mortgage Calculators (By Year)'!M22,NA())) -> 0 | I22: =IF(B22=ROUND(Inputs!$K$10,0),$I$20,NA()) -> #N/A | K22: 0 | L22: =IF($K$20=Inputs!$B$18,IF($K22<='Mortgage Calculators (By Year)'!$C$9,'Mortgage Calculators (By Year)'!D22,NA()),IF($K22<='Mortgage Calculators (By Year)'!$J$12,'Mortgage Calculators (By Year)'!K22,NA())) -> 0 | M22: =IF($K$20=Inputs!$B$18,IF($K22<='Mortgage Calculators (By Year)'!$C$9,'Mortgage Calculators (By Year)'!E22,NA()),IF($K22<='Mortgage Calculators (By Year)'!$J$12,'Mortgage Calculators (By Year)'!L22,NA())) -> 0 | N22: =L22+M22 -> 0 | O22: =IF(K22=ROUND(Inputs!$K$10,0),$O$20,NA()) -> #N/A
B23: 1 | C23: =IF($B$20=Inputs!$B$18,IF($B23<='Mortgage Calculators (By Year)'!$C$9,SUM('Mortgage Calculators (By Year)'!C$22:C23),NA()),IF($B23<='Mortgage Calculators (By Year)'!$J$12,SUM('Mortgage Calculators (By Year)'!J$22:J23),NA())) -> 0 | D23: =IF($B$20=Inputs!$B$18,IF($B23<='Mortgage Calculators (By Year)'!$C$9,SUM('Mortgage Calculators (By Year)'!D$22:D23),NA()),IF($B23<='Mortgage Calculators (By Year)'!$J$12,SUM('Mortgage Calculators (By Year)'!K$22:K23),NA())) -> 0 | E23: =IF($B$20=Inputs!$B$18,IF($B23<='Mortgage Calculators (By Year)'!$C$9,SUM('Mortgage Calculators (By Year)'!E$22:E23),NA()),IF($B23<='Mortgage Calculators (By Year)'!$J$12,SUM('Mortgage Calculators (By Year)'!L$22:L23),NA())) -> 100 | F23: =IF($B$20=Inputs!$B$18,IF($B23<='Mortgage Calculators (By Year)'!$C$9,'Mortgage Calculators (By Year)'!F23,NA()),IF($B23<='Mortgage Calculators (By Year)'!$J$12,'Mortgage Calculators (By Year)'!M23,NA())) -> 0 | G23: =IF($B$20=Inputs!$B$18,IF($B23='Mortgage Calculators (By Year)'!$C$9,D23,""),IF($B23='Mortgage Calculators (By Year)'!$J$12,D23,"")) | H23: =IF($B$20=Inputs!$B$18,IF($B23='Mortgage Calculators (By Year)'!$C$9,E23,""),IF($B23='Mortgage Calculators (By Year)'!$J$12,E23,"")) | I23: =IF(B23=ROUND(Inputs!$K$10,0),$I$20,NA()) -> #N/A | K23: 1 | L23: =IF($K$20=Inputs!$B$18,IF($K23<='Mortgage Calculators (By Year)'!$C$9,'Mortgage Calculators (By Year)'!D23,NA()),IF($K23<='Mortgage Calculators (By Year)'!$J$12,'Mortgage Calculators (By Year)'!K23,NA())) -> 0 | M23: =IF($K$20=Inputs!$B$18,IF($K23<='Mortgage Calculators (By Year)'!$C$9,'Mortgage Calculators (By Year)'!E23,NA()),IF($K23<='Mortgage Calculators (By Year)'!$J$12,'Mortgage Calculators (By Year)'!L23,NA())) -> 100 | N23: =L23+M23 -> 100 | O23: =IF(K23=ROUND(Inputs!$K$10,0),$O$20,NA()) -> #N/A
B24: 2 | C24: =IF($B$20=Inputs!$B$18,IF($B24<='Mortgage Calculators (By Year)'!$C$9,SUM('Mortgage Calculators (By Year)'!C$22:C24),NA()),IF($B24<='Mortgage Calculators (By Year)'!$J$12,SUM('Mortgage Calculators (By Year)'!J$22:J24),NA())) -> 0 | D24: =IF($B$20=Inputs!$B$18,IF($B24<='Mortgage Calculators (By Year)'!$C$9,SUM('Mortgage Calculators (By Year)'!D$22:D24),NA()),IF($B24<='Mortgage Calculators (By Year)'!$J$12,SUM('Mortgage Calculators (By Year)'!K$22:K24),NA())) -> 0 | E24: =IF($B$20=Inputs!$B$18,IF($B24<='Mortgage Calculators (By Year)'!$C$9,SUM('Mortgage Calculators (By Year)'!E$22:E24),NA()),IF($B24<='Mortgage Calculators (By Year)'!$J$12,SUM('Mortgage Calculators (By Year)'!L$22:L24),NA())) -> 200 | F24: =IF($B$20=Inputs!$B$18,IF($B24<='Mortgage Calculators (By Year)'!$C$9,'Mortgage Calculators (By Year)'!F24,NA()),IF($B24<='Mortgage Calculators (By Year)'!$J$12,'Mortgage Calculators (By Year)'!M24,NA())) -> 0 | G24: =IF($B$20=Inputs!$B$18,IF($B24='Mortgage Calculators (By Year)'!$C$9,D24,""),IF($B24='Mortgage Calculators (By Year)'!$J$12,D24,"")) | H24: =IF($B$20=Inputs!$B$18,IF($B24='Mortgage Calculators (By Year)'!$C$9,E24,""),IF($B24='Mortgage Calculators (By Year)'!$J$12,E24,"")) | I24: =IF(B24=ROUND(Inputs!$K$10,0),$I$20,NA()) -> #N/A | K24: 2 | L24: =IF($K$20=Inputs!$B$18,IF($K24<='Mortgage Calculators (By Year)'!$C$9,'Mortgage Calculators (By Year)'!D24,NA()),IF($K24<='Mortgage Calculators (By Year)'!$J$12,'Mortgage Calculators (By Year)'!K24,NA())) -> 0 | M24: =IF($K$20=Inputs!$B$18,IF($K24<='Mortgage Calculators (By Year)'!$C$9,'Mortgage Calculators (By Year)'!E24,NA()),IF($K24<='Mortgage Calculators (By Year)'!$J$12,'Mortgage Calculators (By Year)'!L24,NA())) -> 100 | N24: =L24+M24 -> 100 | O24: =IF(K24=ROUND(Inputs!$K$10,0),$O$20,NA()) -> #N/A
B25: 3 | C25: =IF($B$20=Inputs!$B$18,IF($B25<='Mortgage Calculators (By Year)'!$C$9,SUM('Mortgage Calculators (By Year)'!C$22:C25),NA()),IF($B25<='Mortgage Calculators (By Year)'!$J$12,SUM('Mortgage Calculators (By Year)'!J$22:J25),NA())) -> 0 | D25: =IF($B$20=Inputs!$B$18,IF($B25<='Mortgage Calculators (By Year)'!$C$9,SUM('Mortgage Calculators (By Year)'!D$22:D25),NA()),IF($B25<='Mortgage Calculators (By Year)'!$J$12,SUM('Mortgage Calculators (By Year)'!K$22:K25),NA())) -> 0 | E25: =IF($B$20=Inputs!$B$18,IF($B25<='Mortgage Calculators (By Year)'!$C$9,SUM('Mortgage Calculators (By Year)'!E$22:E25),NA()),IF($B25<='Mortgage Calculators (By Year)'!$J$12,SUM('Mortgage Calculators (By Year)'!L$22:L25),NA())) -> 300 | F25: =IF($B$20=Inputs!$B$18,IF($B25<='Mortgage Calculators (By Year)'!$C$9,'Mortgage Calculators (By Year)'!F25,NA()),IF($B25<='Mortgage Calculators (By Year)'!$J$12,'Mortgage Calculators (By Year)'!M25,NA())) -> 0 | G25: =IF($B$20=Inputs!$B$18,IF($B25='Mortgage Calculators (By Year)'!$C$9,D25,""),IF($B25='Mortgage Calculators (By Year)'!$J$12,D25,"")) | H25: =IF($B$20=Inputs!$B$18,IF($B25='Mortgage Calculators (By Year)'!$C$9,E25,""),IF($B25='Mortgage Calculators (By Year)'!$J$12,E25,"")) | I25: =IF(B25=ROUND(Inputs!$K$10,0),$I$20,NA()) -> #N/A | K25: 3 | L25: =IF($K$20=Inputs!$B$18,IF($K25<='Mortgage Calculators (By Year)'!$C$9,'Mortgage Calculators (By Year)'!D25,NA()),IF($K25<='Mortgage Calculators (By Year)'!$J$12,'Mortgage Calculators (By Year)'!K25,NA())) -> 0 | M25: =IF($K$20=Inputs!$B$18,IF($K25<='Mortgage Calculators (By Year)'!$C$9,'Mortgage Calculators (By Year)'!E25,NA()),IF($K25<='Mortgage Calculators (By Year)'!$J$12,'Mortgage Calculators (By Year)'!L25,NA())) -> 100 | N25: =L25+M25 -> 100 | O25: =IF(K25=ROUND(Inputs!$K$10,0),$O$20,NA()) -> #N/A
B26: 4 | C26: =IF($B$20=Inputs!$B$18,IF($B26<='Mortgage Calculators (By Year)'!$C$9,SUM('Mortgage Calculators (By Year)'!C$22:C26),NA()),IF($B26<='Mortgage Calculators (By Year)'!$J$12,SUM('Mortgage Calculators (By Year)'!J$22:J26),NA())) -> 0 | D26: =IF($B$20=Inputs!$B$18,IF($B26<='Mortgage Calculators (By Year)'!$C$9,SUM('Mortgage Calculators (By Year)'!D$22:D26),NA()),IF($B26<='Mortgage Calculators (By Year)'!$J$12,SUM('Mortgage Calculators (By Year)'!K$22:K26),NA())) -> 0 | E26: =IF($B$20=Inputs!$B$18,IF($B26<='Mortgage Calculators (By Year)'!$C$9,SUM('Mortgage Calculators (By Year)'!E$22:E26),NA()),IF($B26<='Mortgage Calculators (By Year)'!$J$12,SUM('Mortgage Calculators (By Year)'!L$22:L26),NA())) -> 400 | F26: =IF($B$20=Inputs!$B$18,IF($B26<='Mortgage Calculators (By Year)'!$C$9,'Mortgage Calculators (By Year)'!F26,NA()),IF($B26<='Mortgage Calculators (By Year)'!$J$12,'Mortgage Calculators (By Year)'!M26,NA())) -> 0 | G26: =IF($B$20=Inputs!$B$18,IF($B26='Mortgage Calculators (By Year)'!$C$9,D26,""),IF($B26='Mortgage Calculators (By Year)'!$J$12,D26,"")) | H26: =IF($B$20=Inputs!$B$18,IF($B26='Mortgage Calculators (By Year)'!$C$9,E26,""),IF($B26='Mortgage Calculators (By Year)'!$J$12,E26,"")) | I26: =IF(B26=ROUND(Inputs!$K$10,0),$I$20,NA()) -> #N/A | K26: 4 | L26: =IF($K$20=Inputs!$B$18,IF($K26<='Mortgage Calculators (By Year)'!$C$9,'Mortgage Calculators (By Year)'!D26,NA()),IF($K26<='Mortgage Calculators (By Year)'!$J$12,'Mortgage Calculators (By Year)'!K26,NA())) -> 0 | M26: =IF($K$20=Inputs!$B$18,IF($K26<='Mortgage Calculators (By Year)'!$C$9,'Mortgage Calculators (By Year)'!E26,NA()),IF($K26<='Mortgage Calculators (By Year)'!$J$12,'Mortgage Calculators (By Year)'!L26,NA())) -> 100 | N26: =L26+M26 -> 100 | O26: =IF(K26=ROUND(Inputs!$K$10,0),$O$20,NA()) -> #N/A
B27: 5 | C27: =IF($B$20=Inputs!$B$18,IF($B27<='Mortgage Calculators (By Year)'!$C$9,SUM('Mortgage Calculators (By Year)'!C$22:C27),NA()),IF($B27<='Mortgage Calculators (By Year)'!$J$12,SUM('Mortgage Calculators (By Year)'!J$22:J27),NA())) -> 0 | D27: =IF($B$20=Inputs!$B$18,IF($B27<='Mortgage Calculators (By Year)'!$C$9,SUM('Mortgage Calculators (By Year)'!D$22:D27),NA()),IF($B27<='Mortgage Calculators (By Year)'!$J$12,SUM('Mortgage Calculators (By Year)'!K$22:K27),NA())) -> 0 | E27: =IF($B$20=Inputs!$B$18,IF($B27<='Mortgage Calculators (By Year)'!$C$9,SUM('Mortgage Calculators (By Year)'!E$22:E27),NA()),IF($B27<='Mortgage Calculators (By Year)'!$J$12,SUM('Mortgage Calculators (By Year)'!L$22:L27),NA())) -> 500 | F27: =IF($B$20=Inputs!$B$18,IF($B27<='Mortgage Calculators (By Year)'!$C$9,'Mortgage Calculators (By Year)'!F27,NA()),IF($B27<='Mortgage Calculators (By Year)'!$J$12,'Mortgage Calculators (By Year)'!M27,NA())) -> 0 | G27: =IF($B$20=Inputs!$B$18,IF($B27='Mortgage Calculators (By Year)'!$C$9,D27,""),IF($B27='Mortgage Calculators (By Year)'!$J$12,D27,"")) | H27: =IF($B$20=Inputs!$B$18,IF($B27='Mortgage Calculators (By Year)'!$C$9,E27,""),IF($B27='Mortgage Calculators (By Year)'!$J$12,E27,"")) | I27: =IF(B27=ROUND(Inputs!$K$10,0),$I$20,NA()) -> 3000 | K27: 5 | L27: =IF($K$20=Inputs!$B$18,IF($K27<='Mortgage Calculators (By Year)'!$C$9,'Mortgage Calculators (By Year)'!D27,NA()),IF($K27<='Mortgage Calculators (By Year)'!$J$12,'Mortgage Calculators (By Year)'!K27,NA())) -> 0 | M27: =IF($K$20=Inputs!$B$18,IF($K27<='Mortgage Calculators (By Year)'!$C$9,'Mortgage Calculators (By Year)'!E27,NA()),IF($K27<='Mortgage Calculators (By Year)'!$J$12,'Mortgage Calculators (By Year)'!L27,NA())) -> 100 | N27: =L27+M27 -> 100 | O27: =IF(K27=ROUND(Inputs!$K$10,0),$O$20,NA()) -> 100
B28: 6 | C28: =IF($B$20=Inputs!$B$18,IF($B28<='Mortgage Calculators (By Year)'!$C$9,SUM('Mortgage Calculators (By Year)'!C$22:C28),NA()),IF($B28<='Mortgage Calculators (By Year)'!$J$12,SUM('Mortgage Calculators (By Year)'!J$22:J28),NA())) -> 0 | D28: =IF($B$20=Inputs!$B$18,IF($B28<='Mortgage Calculators (By Year)'!$C$9,SUM('Mortgage Calculators (By Year)'!D$22:D28),NA()),IF($B28<='Mortgage Calculators (By Year)'!$J$12,SUM('Mortgage Calculators (By Year)'!K$22:K28),NA())) -> 0 | E28: =IF($B$20=Inputs!$B$18,IF($B28<='Mortgage Calculators (By Year)'!$C$9,SUM('Mortgage Calculators (By Year)'!E$22:E28),NA()),IF($B28<='Mortgage Calculators (By Year)'!$J$12,SUM('Mortgage Calculators (By Year)'!L$22:L28),NA())) -> 600 | F28: =IF($B$20=Inputs!$B$18,IF($B28<='Mortgage Calculators (By Year)'!$C$9,'Mortgage Calculators (By Year)'!F28,NA()),IF($B28<='Mortgage Calculators (By Year)'!$J$12,'Mortgage Calculators (By Year)'!M28,NA())) -> 0 | G28: =IF($B$20=Inputs!$B$18,IF($B28='Mortgage Calculators (By Year)'!$C$9,D28,""),IF($B28='Mortgage Calculators (By Year)'!$J$12,D28,"")) | H28: =IF($B$20=Inputs!$B$18,IF($B28='Mortgage Calculators (By Year)'!$C$9,E28,""),IF($B28='Mortgage Calculators (By Year)'!$J$12,E28,"")) | I28: =IF(B28=ROUND(Inputs!$K$10,0),$I$20,NA()) -> #N/A | K28: 6 | L28: =IF($K$20=Inputs!$B$18,IF($K28<='Mortgage Calculators (By Year)'!$C$9,'Mortgage Calculators (By Year)'!D28,NA()),IF($K28<='Mortgage Calculators (By Year)'!$J$12,'Mortgage Calculators (By Year)'!K28,NA())) -> 0 | M28: =IF($K$20=Inputs!$B$18,IF($K28<='Mortgage Calculators (By Year)'!$C$9,'Mortgage Calculators (By Year)'!E28,NA()),IF($K28<='Mortgage Calculators (By Year)'!$J$12,'Mortgage Calculators (By Year)'!L28,NA())) -> 100 | N28: =L28+M28 -> 100 | O28: =IF(K28=ROUND(Inputs!$K$10,0),$O$20,NA()) -> #N/A
B29: 7 | C29: =IF($B$20=Inputs!$B$18,IF($B29<='Mortgage Calculators (By Year)'!$C$9,SUM('Mortgage Calculators (By Year)'!C$22:C29),NA()),IF($B29<='Mortgage Calculators (By Year)'!$J$12,SUM('Mortgage Calculators (By Year)'!J$22:J29),NA())) -> 0 | D29: =IF($B$20=Inputs!$B$18,IF($B29<='Mortgage Calculators (By Year)'!$C$9,SUM('Mortgage Calculators (By Year)'!D$22:D29),NA()),IF($B29<='Mortgage Calculators (By Year)'!$J$12,SUM('Mortgage Calculators (By Year)'!K$22:K29),NA())) -> 0 | E29: =IF($B$20=Inputs!$B$18,IF($B29<='Mortgage Calculators (By Year)'!$C$9,SUM('Mortgage Calculators (By Year)'!E$22:E29),NA()),IF($B29<='Mortgage Calculators (By Year)'!$J$12,SUM('Mortgage Calculators (By Year)'!L$22:L29),NA())) -> 700 | F29: =IF($B$20=Inputs!$B$18,IF($B29<='Mortgage Calculators (By Year)'!$C$9,'Mortgage Calculators (By Year)'!F29,NA()),IF($B29<='Mortgage Calculators (By Year)'!$J$12,'Mortgage Calculators (By Year)'!M29,NA())) -> 0 | G29: =IF($B$20=Inputs!$B$18,IF($B29='Mortgage Calculators (By Year)'!$C$9,D29,""),IF($B29='Mortgage Calculators (By Year)'!$J$12,D29,"")) | H29: =IF($B$20=Inputs!$B$18,IF($B29='Mortgage Calculators (By Year)'!$C$9,E29,""),IF($B29='Mortgage Calculators (By Year)'!$J$12,E29,"")) | I29: =IF(B29=ROUND(Inputs!$K$10,0),$I$20,NA()) -> #N/A | K29: 7 | L29: =IF($K$20=Inputs!$B$18,IF($K29<='Mortgage Calculators (By Year)'!$C$9,'Mortgage Calculators (By Year)'!D29,NA()),IF($K29<='Mortgage Calculators (By Year)'!$J$12,'Mortgage Calculators (By Year)'!K29,NA())) -> 0 | M29: =IF($K$20=Inputs!$B$18,IF($K29<='Mortgage Calculators (By Year)'!$C$9,'Mortgage Calculators (By Year)'!E29,NA()),IF($K29<='Mortgage Calculators (By Year)'!$J$12,'Mortgage Calculators (By Year)'!L29,NA())) -> 100 | N29: =L29+M29 -> 100 | O29: =IF(K29=ROUND(Inputs!$K$10,0),$O$20,NA()) -> #N/A
B30: 8 | C30: =IF($B$20=Inputs!$B$18,IF($B30<='Mortgage Calculators (By Year)'!$C$9,SUM('Mortgage Calculators (By Year)'!C$22:C30),NA()),IF($B30<='Mortgage Calculators (By Year)'!$J$12,SUM('Mortgage Calculators (By Year)'!J$22:J30),NA())) -> 0 | D30: =IF($B$20=Inputs!$B$18,IF($B30<='Mortgage Calculators (By Year)'!$C$9,SUM('Mortgage Calculators (By Year)'!D$22:D30),NA()),IF($B30<='Mortgage Calculators (By Year)'!$J$12,SUM('Mortgage Calculators (By Year)'!K$22:K30),NA())) -> 0 | E30: =IF($B$20=Inputs!$B$18,IF($B30<='Mortgage Calculators (By Year)'!$C$9,SUM('Mortgage Calculators (By Year)'!E$22:E30),NA()),IF($B30<='Mortgage Calculators (By Year)'!$J$12,SUM('Mortgage Calculators (By Year)'!L$22:L30),NA())) -> 800 | F30: =IF($B$20=Inputs!$B$18,IF($B30<='Mortgage Calculators (By Year)'!$C$9,'Mortgage Calculators (By Year)'!F30,NA()),IF($B30<='Mortgage Calculators (By Year)'!$J$12,'Mortgage Calculators (By Year)'!M30,NA())) -> 0 | G30: =IF($B$20=Inputs!$B$18,IF($B30='Mortgage Calculators (By Year)'!$C$9,D30,""),IF($B30='Mortgage Calculators (By Year)'!$J$12,D30,"")) | H30: =IF($B$20=Inputs!$B$18,IF($B30='Mortgage Calculators (By Year)'!$C$9,E30,""),IF($B30='Mortgage Calculators (By Year)'!$J$12,E30,"")) | I30: =IF(B30=ROUND(Inputs!$K$10,0),$I$20,NA()) -> #N/A | K30: 8 | L30: =IF($K$20=Inputs!$B$18,IF($K30<='Mortgage Calculators (By Year)'!$C$9,'Mortgage Calculators (By Year)'!D30,NA()),IF($K30<='Mortgage Calculators (By Year)'!$J$12,'Mortgage Calculators (By Year)'!K30,NA())) -> 0 | M30: =IF($K$20=Inputs!$B$18,IF($K30<='Mortgage Calculators (By Year)'!$C$9,'Mortgage Calculators (By Year)'!E30,NA()),IF($K30<='Mortgage Calculators (By Year)'!$J$12,'Mortgage Calculators (By Year)'!L30,NA())) -> 100 | N30: =L30+M30 -> 100 | O30: =IF(K30=ROUND(Inputs!$K$10,0),$O$20,NA()) -> #N/A
B31: 9 | C31: =IF($B$20=Inputs!$B$18,IF($B31<='Mortgage Calculators (By Year)'!$C$9,SUM('Mortgage Calculators (By Year)'!C$22:C31),NA()),IF($B31<='Mortgage Calculators (By Year)'!$J$12,SUM('Mortgage Calculators (By Year)'!J$22:J31),NA())) -> 0 | D31: =IF($B$20=Inputs!$B$18,IF($B31<='Mortgage Calculators (By Year)'!$C$9,SUM('Mortgage Calculators (By Year)'!D$22:D31),NA()),IF($B31<='Mortgage Calculators (By Year)'!$J$12,SUM('Mortgage Calculators (By Year)'!K$22:K31),NA())) -> 0 | E31: =IF($B$20=Inputs!$B$18,IF($B31<='Mortgage Calculators (By Year)'!$C$9,SUM('Mortgage Calculators (By Year)'!E$22:E31),NA()),IF($B31<='Mortgage Calculators (By Year)'!$J$12,SUM('Mortgage Calculators (By Year)'!L$22:L31),NA())) -> 900 | F31: =IF($B$20=Inputs!$B$18,IF($B31<='Mortgage Calculators (By Year)'!$C$9,'Mortgage Calculators (By Year)'!F31,NA()),IF($B31<='Mortgage Calculators (By Year)'!$J$12,'Mortgage Calculators (By Year)'!M31,NA())) -> 0 | G31: =IF($B$20=Inputs!$B$18,IF($B31='Mortgage Calculators (By Year)'!$C$9,D31,""),IF($B31='Mortgage Calculators (By Year)'!$J$12,D31,"")) | H31: =IF($B$20=Inputs!$B$18,IF($B31='Mortgage Calculators (By Year)'!$C$9,E31,""),IF($B31='Mortgage Calculators (By Year)'!$J$12,E31,"")) | I31: =IF(B31=ROUND(Inputs!$K$10,0),$I$20,NA()) -> #N/A | K31: 9 | L31: =IF($K$20=Inputs!$B$18,IF($K31<='Mortgage Calculators (By Year)'!$C$9,'Mortgage Calculators (By Year)'!D31,NA()),IF($K31<='Mortgage Calculators (By Year)'!$J$12,'Mortgage Calculators (By Year)'!K31,NA())) -> 0 | M31: =IF($K$20=Inputs!$B$18,IF($K31<='Mortgage Calculators (By Year)'!$C$9,'Mortgage Calculators (By Year)'!E31,NA()),IF($K31<='Mortgage Calculators (By Year)'!$J$12,'Mortgage Calculators (By Year)'!L31,NA())) -> 100 | N31: =L31+M31 -> 100 | O31: =IF(K31=ROUND(Inputs!$K$10,0),$O$20,NA()) -> #N/A
B32: 10 | C32: =IF($B$20=Inputs!$B$18,IF($B32<='Mortgage Calculators (By Year)'!$C$9,SUM('Mortgage Calculators (By Year)'!C$22:C32),NA()),IF($B32<='Mortgage Calculators (By Year)'!$J$12,SUM('Mortgage Calculators (By Year)'!J$22:J32),NA())) -> 0 | D32: =IF($B$20=Inputs!$B$18,IF($B32<='Mortgage Calculators (By Year)'!$C$9,SUM('Mortgage Calculators (By Year)'!D$22:D32),NA()),IF($B32<='Mortgage Calculators (By Year)'!$J$12,SUM('Mortgage Calculators (By Year)'!K$22:K32),NA())) -> 0 | E32: =IF($B$20=Inputs!$B$18,IF($B32<='Mortgage Calculators (By Year)'!$C$9,SUM('Mortgage Calculators (By Year)'!E$22:E32),NA()),IF($B32<='Mortgage Calculators (By Year)'!$J$12,SUM('Mortgage Calculators (By Year)'!L$22:L32),NA())) -> 1000 | F32: =IF($B$20=Inputs!$B$18,IF($B32<='Mortgage Calculators (By Year)'!$C$9,'Mortgage Calculators (By Year)'!F32,NA()),IF($B32<='Mortgage Calculators (By Year)'!$J$12,'Mortgage Calculators (By Year)'!M32,NA())) -> 0 | G32: =IF($B$20=Inputs!$B$18,IF($B32='Mortgage Calculators (By Year)'!$C$9,D32,""),IF($B32='Mortgage Calculators (By Year)'!$J$12,D32,"")) | H32: =IF($B$20=Inputs!$B$18,IF($B32='Mortgage Calculators (By Year)'!$C$9,E32,""),IF($B32='Mortgage Calculators (By Year)'!$J$12,E32,"")) | I32: =IF(B32=ROUND(Inputs!$K$10,0),$I$20,NA()) -> #N/A | K32: 10 | L32: =IF($K$20=Inputs!$B$18,IF($K32<='Mortgage Calculators (By Year)'!$C$9,'Mortgage Calculators (By Year)'!D32,NA()),IF($K32<='Mortgage Calculators (By Year)'!$J$12,'Mortgage Calculators (By Year)'!K32,NA())) -> 0 | M32: =IF($K$20=Inputs!$B$18,IF($K32<='Mortgage Calculators (By Year)'!$C$9,'Mortgage Calculators (By Year)'!E32,NA()),IF($K32<='Mortgage Calculators (By Year)'!$J$12,'Mortgage Calculators (By Year)'!L32,NA())) -> 100 | N32: =L32+M32 -> 100 | O32: =IF(K32=ROUND(Inputs!$K$10,0),$O$20,NA()) -> #N/A
B33: 11 | C33: =IF($B$20=Inputs!$B$18,IF($B33<='Mortgage Calculators (By Year)'!$C$9,SUM('Mortgage Calculators (By Year)'!C$22:C33),NA()),IF($B33<='Mortgage Calculators (By Year)'!$J$12,SUM('Mortgage Calculators (By Year)'!J$22:J33),NA())) -> 0 | D33: =IF($B$20=Inputs!$B$18,IF($B33<='Mortgage Calculators (By Year)'!$C$9,SUM('Mortgage Calculators (By Year)'!D$22:D33),NA()),IF($B33<='Mortgage Calculators (By Year)'!$J$12,SUM('Mortgage Calculators (By Year)'!K$22:K33),NA())) -> 0 | E33: =IF($B$20=Inputs!$B$18,IF($B33<='Mortgage Calculators (By Year)'!$C$9,SUM('Mortgage Calculators (By Year)'!E$22:E33),NA()),IF($B33<='Mortgage Calculators (By Year)'!$J$12,SUM('Mortgage Calculators (By Year)'!L$22:L33),NA())) -> 1100 | F33: =IF($B$20=Inputs!$B$18,IF($B33<='Mortgage Calculators (By Year)'!$C$9,'Mortgage Calculators (By Year)'!F33,NA()),IF($B33<='Mortgage Calculators (By Year)'!$J$12,'Mortgage Calculators (By Year)'!M33,NA())) -> 0 | G33: =IF($B$20=Inputs!$B$18,IF($B33='Mortgage Calculators (By Year)'!$C$9,D33,""),IF($B33='Mortgage Calculators (By Year)'!$J$12,D33,"")) | H33: =IF($B$20=Inputs!$B$18,IF($B33='Mortgage Calculators (By Year)'!$C$9,E33,""),IF($B33='Mortgage Calculators (By Year)'!$J$12,E33,"")) | I33: =IF(B33=ROUND(Inputs!$K$10,0),$I$20,NA()) -> #N/A | K33: 11 | L33: =IF($K$20=Inputs!$B$18,IF($K33<='Mortgage Calculators (By Year)'!$C$9,'Mortgage Calculators (By Year)'!D33,NA()),IF($K33<='Mortgage Calculators (By Year)'!$J$12,'Mortgage Calculators (By Year)'!K33,NA())) -> 0 | M33: =IF($K$20=Inputs!$B$18,IF($K33<='Mortgage Calculators (By Year)'!$C$9,'Mortgage Calculators (By Year)'!E33,NA()),IF($K33<='Mortgage Calculators (By Year)'!$J$12,'Mortgage Calculators (By Year)'!L33,NA())) -> 100 | N33: =L33+M33 -> 100 | O33: =IF(K33=ROUND(Inputs!$K$10,0),$O$20,NA()) -> #N/A
B34: 12 | C34: =IF($B$20=Inputs!$B$18,IF($B34<='Mortgage Calculators (By Year)'!$C$9,SUM('Mortgage Calculators (By Year)'!C$22:C34),NA()),IF($B34<='Mortgage Calculators (By Year)'!$J$12,SUM('Mortgage Calculators (By Year)'!J$22:J34),NA())) -> 0 | D34: =IF($B$20=Inputs!$B$18,IF($B34<='Mortgage Calculators (By Year)'!$C$9,SUM('Mortgage Calculators (By Year)'!D$22:D34),NA()),IF($B34<='Mortgage Calculators (By Year)'!$J$12,SUM('Mortgage Calculators (By Year)'!K$22:K34),NA())) -> 0 | E34: =IF($B$20=Inputs!$B$18,IF($B34<='Mortgage Calculators (By Year)'!$C$9,SUM('Mortgage Calculators (By Year)'!E$22:E34),NA()),IF($B34<='Mortgage Calculators (By Year)'!$J$12,SUM('Mortgage Calculators (By Year)'!L$22:L34),NA())) -> 1200 | F34: =IF($B$20=Inputs!$B$18,IF($B34<='Mortgage Calculators (By Year)'!$C$9,'Mortgage Calculators (By Year)'!F34,NA()),IF($B34<='Mortgage Calculators (By Year)'!$J$12,'Mortgage Calculators (By Year)'!M34,NA())) -> 0 | G34: =IF($B$20=Inputs!$B$18,IF($B34='Mortgage Calculators (By Year)'!$C$9,D34,""),IF($B34='Mortgage Calculators (By Year)'!$J$12,D34,"")) | H34: =IF($B$20=Inputs!$B$18,IF($B34='Mortgage Calculators (By Year)'!$C$9,E34,""),IF($B34='Mortgage Calculators (By Year)'!$J$12,E34,"")) | I34: =IF(B34=ROUND(Inputs!$K$10,0),$I$20,NA()) -> #N/A | K34: 12 | L34: =IF($K$20=Inputs!$B$18,IF($K34<='Mortgage Calculators (By Year)'!$C$9,'Mortgage Calculators (By Year)'!D34,NA()),IF($K34<='Mortgage Calculators (By Year)'!$J$12,'Mortgage Calculators (By Year)'!K34,NA())) -> 0 | M34: =IF($K$20=Inputs!$B$18,IF($K34<='Mortgage Calculators (By Year)'!$C$9,'Mortgage Calculators (By Year)'!E34,NA()),IF($K34<='Mortgage Calculators (By Year)'!$J$12,'Mortgage Calculators (By Year)'!L34,NA())) -> 100 | N34: =L34+M34 -> 100 | O34: =IF(K34=ROUND(Inputs!$K$10,0),$O$20,NA()) -> #N/A
... B73: 51 | C73: =IF($B$20=Inputs!$B$18,IF($B73<='Mortgage Calculators (By Year)'!$C$9,SUM('Mortgage Calculators (By Year)'!C$22:C73),NA()),IF($B73<='Mortgage Calculators (By Year)'!$J$12,SUM('Mortgage Calculators (By Year)'!J$22:J73),NA())) -> #N/A | D73: =IF($B$20=Inputs!$B$18,IF($B73<='Mortgage Calculators (By Year)'!$C$9,SUM('Mortgage Calculators (By Year)'!D$22:D73),NA()),IF($B73<='Mortgage Calculators (By Year)'!$J$12,SUM('Mortgage Calculators (By Year)'!K$22:K73),NA())) -> #N/A | E73: =IF($B$20=Inputs!$B$18,IF($B73<='Mortgage Calculators (By Year)'!$C$9,SUM('Mortgage Calculators (By Year)'!E$22:E73),NA()),IF($B73<='Mortgage Calculators (By Year)'!$J$12,SUM('Mortgage Calculators (By Year)'!L$22:L73),NA())) -> #N/A | F73: =IF($B$20=Inputs!$B$18,IF($B73<='Mortgage Calculators (By Year)'!$C$9,'Mortgage Calculators (By Year)'!F73,NA()),IF($B73<='Mortgage Calculators (By Year)'!$J$12,'Mortgage Calculators (By Year)'!M73,NA())) -> #N/A | G73: =IF($B$20=Inputs!$B$18,IF($B73='Mortgage Calculators (By Year)'!$C$9,D73,""),IF($B73='Mortgage Calculators (By Year)'!$J$12,D73,"")) | H73: =IF($B$20=Inputs!$B$18,IF($B73='Mortgage Calculators (By Year)'!$C$9,E73,""),IF($B73='Mortgage Calculators (By Year)'!$J$12,E73,"")) | I73: =IF(B73=ROUND(Inputs!$K$10,0),$I$20,NA()) -> #N/A | K73: 51 | L73: =IF($K$20=Inputs!$B$18,IF($K73<='Mortgage Calculators (By Year)'!$C$9,'Mortgage Calculators (By Year)'!D73,NA()),IF($K73<='Mortgage Calculators (By Year)'!$J$12,'Mortgage Calculators (By Year)'!K73,NA())) -> #N/A | M73: =IF($K$20=Inputs!$B$18,IF($K73<='Mortgage Calculators (By Year)'!$C$9,'Mortgage Calculators (By Year)'!E73,NA()),IF($K73<='Mortgage Calculators (By Year)'!$J$12,'Mortgage Calculators (By Year)'!L73,NA())) -> #N/A | N73: =L73+M73 -> #N/A | O73: =IF(K73=ROUND(Inputs!$K$10,0),$O$20,NA()) -> #N/A
B75: CHARTS FOR ANALYSIS SUMMARY TAB (PG 2)
B76: Property and Equity Growth | G76: Annual Payments
B77: ='Analysis Summary'!$E$6 -> Principal & Interest Loan (P&I) | E77: =_xlfn.XLOOKUP(Inputs!$K$10,'RE Calculations'!$B$79:$B$130,'RE Calculations'!$C$79:$C$130) -> 2086720.4 | G77: ='Analysis Summary'!$E$6 -> Principal & Interest Loan (P&I) | L77: =_xlfn.MAXIFS(H79:I130,H79:I130,">0") -> 10874230
B78: Year | C78: Property Value | D78: Equity Value | E78: Holding Period | G78: Year | H78: Gross Profit | I78: Net Profit | J78: Gross Annualized ROI | K78: Net Annualized ROI | L78: Holding Period
B79: 0 | C79: =IF($B$77=Inputs!$B$18,IF($B79<='Mortgage Calculators (By Year)'!$C$9,'Forecast (By Year)'!G4,NA()),IF($B79<='Mortgage Calculators (By Year)'!$J$12,'Forecast (By Year)'!AE4,NA())) -> 1635000 | D79: =IF($B$77=Inputs!$B$18,IF($B79<='Mortgage Calculators (By Year)'!$C$9,'Forecast (By Year)'!H4,NA()),IF($B79<='Mortgage Calculators (By Year)'!$J$12,'Forecast (By Year)'!AF4,NA())) -> 1635000 | E79: =IF(B79=ROUND(Inputs!$K$10,0),$E$77,NA()) -> #N/A | G79: 0 | H79: =IF($K$20=Inputs!$B$18,IF($G79<='Mortgage Calculators (By Year)'!$C$9,'Forecast (By Year)'!V4,NA()),IF($G79<='Mortgage Calculators (By Year)'!$J$12,'Forecast (By Year)'!AT4,NA())) -> -3227 | I79: =IF($K$20=Inputs!$B$18,IF($G79<='Mortgage Calculators (By Year)'!$C$9,'Forecast (By Year)'!Y4,NA()),IF($G79<='Mortgage Calculators (By Year)'!$J$12,'Forecast (By Year)'!AW4,NA())) -> -3227 | J79: =IF($K$20=Inputs!$B$18,IF($G79<='Mortgage Calculators (By Year)'!$C$9,'Forecast (By Year)'!X4,NA()),IF($G79<='Mortgage Calculators (By Year)'!$J$12,'Forecast (By Year)'!AV4,NA())) -> - | K79: =IF($K$20=Inputs!$B$18,IF($G79<='Mortgage Calculators (By Year)'!$C$9,'Forecast (By Year)'!AA4,NA()),IF($G79<='Mortgage Calculators (By Year)'!$J$12,'Forecast (By Year)'!AY4,NA())) -> - | L79: =IF(G79=ROUND(Inputs!$K$10,0),$L$77,NA()) -> #N/A
B80: 1 | C80: =IF($B$77=Inputs!$B$18,IF($B80<='Mortgage Calculators (By Year)'!$C$9,'Forecast (By Year)'!G5,NA()),IF($B80<='Mortgage Calculators (By Year)'!$J$12,'Forecast (By Year)'!AE5,NA())) -> 1716750 | D80: =IF($B$77=Inputs!$B$18,IF($B80<='Mortgage Calculators (By Year)'!$C$9,'Forecast (By Year)'!H5,NA()),IF($B80<='Mortgage Calculators (By Year)'!$J$12,'Forecast (By Year)'!AF5,NA())) -> 1716750 | E80: =IF(B80=ROUND(Inputs!$K$10,0),$E$77,NA()) -> #N/A | G80: 1 | H80: =IF($K$20=Inputs!$B$18,IF($G80<='Mortgage Calculators (By Year)'!$C$9,'Forecast (By Year)'!V5,NA()),IF($G80<='Mortgage Calculators (By Year)'!$J$12,'Forecast (By Year)'!AT5,NA())) -> 76888 | I80: =IF($K$20=Inputs!$B$18,IF($G80<='Mortgage Calculators (By Year)'!$C$9,'Forecast (By Year)'!Y5,NA()),IF($G80<='Mortgage Calculators (By Year)'!$J$12,'Forecast (By Year)'!AW5,NA())) -> 150700 | J80: =IF($K$20=Inputs!$B$18,IF($G80<='Mortgage Calculators (By Year)'!$C$9,'Forecast (By Year)'!X5,NA()),IF($G80<='Mortgage Calculators (By Year)'!$J$12,'Forecast (By Year)'!AV5,NA())) -> 0.048024174 | K80: =IF($K$20=Inputs!$B$18,IF($G80<='Mortgage Calculators (By Year)'!$C$9,'Forecast (By Year)'!AA5,NA()),IF($G80<='Mortgage Calculators (By Year)'!$J$12,'Forecast (By Year)'!AY5,NA())) -> 0.094127082 | L80: =IF(G80=ROUND(Inputs!$K$10,0),$L$77,NA()) -> #N/A
B81: 2 | C81: =IF($B$77=Inputs!$B$18,IF($B81<='Mortgage Calculators (By Year)'!$C$9,'Forecast (By Year)'!G6,NA()),IF($B81<='Mortgage Calculators (By Year)'!$J$12,'Forecast (By Year)'!AE6,NA())) -> 1802587.5 | D81: =IF($B$77=Inputs!$B$18,IF($B81<='Mortgage Calculators (By Year)'!$C$9,'Forecast (By Year)'!H6,NA()),IF($B81<='Mortgage Calculators (By Year)'!$J$12,'Forecast (By Year)'!AF6,NA())) -> 1802587.5 | E81: =IF(B81=ROUND(Inputs!$K$10,0),$E$77,NA()) -> #N/A | G81: 2 | H81: =IF($K$20=Inputs!$B$18,IF($G81<='Mortgage Calculators (By Year)'!$C$9,'Forecast (By Year)'!V6,NA()),IF($G81<='Mortgage Calculators (By Year)'!$J$12,'Forecast (By Year)'!AT6,NA())) -> 161008.75 | I81: =IF($K$20=Inputs!$B$18,IF($G81<='Mortgage Calculators (By Year)'!$C$9,'Forecast (By Year)'!Y6,NA()),IF($G81<='Mortgage Calculators (By Year)'!$J$12,'Forecast (By Year)'!AW6,NA())) -> 313216.25 | J81: =IF($K$20=Inputs!$B$18,IF($G81<='Mortgage Calculators (By Year)'!$C$9,'Forecast (By Year)'!X6,NA()),IF($G81<='Mortgage Calculators (By Year)'!$J$12,'Forecast (By Year)'!AV6,NA())) -> 0.050282959 | K81: =IF($K$20=Inputs!$B$18,IF($G81<='Mortgage Calculators (By Year)'!$C$9,'Forecast (By Year)'!AA6,NA()),IF($G81<='Mortgage Calculators (By Year)'!$J$12,'Forecast (By Year)'!AY6,NA())) -> 0.097817292 | L81: =IF(G81=ROUND(Inputs!$K$10,0),$L$77,NA()) -> #N/A
B82: 3 | C82: =IF($B$77=Inputs!$B$18,IF($B82<='Mortgage Calculators (By Year)'!$C$9,'Forecast (By Year)'!G7,NA()),IF($B82<='Mortgage Calculators (By Year)'!$J$12,'Forecast (By Year)'!AE7,NA())) -> 1892716.9 | D82: =IF($B$77=Inputs!$B$18,IF($B82<='Mortgage Calculators (By Year)'!$C$9,'Forecast (By Year)'!H7,NA()),IF($B82<='Mortgage Calculators (By Year)'!$J$12,'Forecast (By Year)'!AF7,NA())) -> 1892716.9 | E82: =IF(B82=ROUND(Inputs!$K$10,0),$E$77,NA()) -> #N/A | G82: 3 | H82: =IF($K$20=Inputs!$B$18,IF($G82<='Mortgage Calculators (By Year)'!$C$9,'Forecast (By Year)'!V7,NA()),IF($G82<='Mortgage Calculators (By Year)'!$J$12,'Forecast (By Year)'!AT7,NA())) -> 249335.54 | I82: =IF($K$20=Inputs!$B$18,IF($G82<='Mortgage Calculators (By Year)'!$C$9,'Forecast (By Year)'!Y7,NA()),IF($G82<='Mortgage Calculators (By Year)'!$J$12,'Forecast (By Year)'!AW7,NA())) -> 484751.21 | J82: =IF($K$20=Inputs!$B$18,IF($G82<='Mortgage Calculators (By Year)'!$C$9,'Forecast (By Year)'!X7,NA()),IF($G82<='Mortgage Calculators (By Year)'!$J$12,'Forecast (By Year)'!AV7,NA())) -> 0.051911583 | K82: =IF($K$20=Inputs!$B$18,IF($G82<='Mortgage Calculators (By Year)'!$C$9,'Forecast (By Year)'!AA7,NA()),IF($G82<='Mortgage Calculators (By Year)'!$J$12,'Forecast (By Year)'!AY7,NA())) -> 0.10092505 | L82: =IF(G82=ROUND(Inputs!$K$10,0),$L$77,NA()) -> #N/A
...

Sheet Mortgage Calculators (By Month)
B2: PRINCIPAL & INTEREST LOAN (P&I) | I2: INTEREST ONLY LOAN (IO) | P2: MORTGAGE CALCULATOR - PRINCIPAL & INTEREST (COMPARISON) | W2: MORTGAGE CALCULATOR - INTEREST ONLY (COMPARISON)
B3: Total Price | C3: =Inputs!K5 -> 1499950 | I3: Total Price | J3: =C3 -> 1499950 | P3: Total Price | Q3: =C3 -> 1499950 | W3: Total Price | X3: =J3 -> 1499950
B4: Down Payment (%) | C4: =Inputs!K6 -> 1 | I4: Down Payment (%) | J4: =C4 -> 1 | P4: Down Payment (%) | Q4: =C4 -> 1 | W4: Down Payment (%) | X4: =J4 -> 1
B5: Down Payment ($) | C5: =C4*C3 -> 1499950 | I5: Down Payment ($) | J5: =J4*J3 -> 1499950 | P5: Down Payment ($) | Q5: =Q4*Q3 -> 1499950 | W5: Down Payment ($) | X5: =X4*X3 -> 1499950
B6: Principal Amount | C6: =C3-C5 -> 0 | I6: Principal Amount | J6: =J3-J5 -> 0 | P6: Principal Amount | Q6: =Q3-Q5 -> 0 | W6: Principal Amount | X6: =X3-X5 -> 0
B7: Annual Interest Rate | C7: =Inputs!K35 -> 0.045 | I7: Annual Interest Rate | J7: =Inputs!K42 -> 0.0475 | P7: Annual Interest Rate | Q7: 0.06 | W7: Annual Interest Rate | X7: 0.062
B8: Equivalent Monthly Interest Rate | C8: =C7/12 -> 0.00375 | I8: Equivalent Monthly Interest Rate | J8: =J7/12 -> 0.0039583333 | P8: Equivalent Monthly Interest Rate | Q8: =Q7/12 -> 0.005 | W8: Equivalent Monthly Interest Rate | X8: =X7/12 -> 0.0051666667
B9: Loan Duration (Years) | C9: =Inputs!K37 -> 30 | I9: Interest Only Duration (Years) | J9: =Inputs!K44 -> 5 | P9: Loan Duration (Years) | Q9: =C9 -> 30 | W9: Interest Only Duration (Years) | X9: =J9 -> 5
B10: Fees | C10: =Inputs!C21 -> 100 | D10: =Inputs!D21 -> per annum | I10: Standard Interest Rate | J10: =Inputs!K45 -> 0.045 | P10: Fees | Q10: =C10 -> 100 | R10: =D10 -> per annum | W10: Standard Interest Rate | X10: 0.06
I11: Equivalent Monthly Interest Rate | J11: =J10/12 -> 0.00375 | W11: Equivalent Monthly Interest Rate | X11: =X10/12 -> 0.005
B12: Monthly Loan Payment | C12: =-PMT(C8,C9*12,C6)+$C$10*_xlfn.XLOOKUP($D$10,'RE Calculations'!$B$12:$B$16,'RE Calculations'!$C$12:$C$16,"ERROR - Check Input")/12 -> 8.3333333 | I12: Total Loan Duration (Years) | J12: =Inputs!K47 -> 30 | P12: Monthly Loan Payment | Q12: =-PMT(Q8,Q9*12,Q6)+$Q$10*_xlfn.XLOOKUP($R$10,'RE Calculations'!$B$12:$B$16,'RE Calculations'!$C$12:$C$16,"ERROR - Check Input")/12 -> 8.3333333 | W12: Total Loan Duration (Years) | X12: =J12 -> 30
B13: Check | C13: =C6*((C8*((1+C8)^(C9*12)))/(((1+C8)^(C9*12))-1))+$C$10*_xlfn.XLOOKUP($D$10,'RE Calculations'!$B$12:$B$16,'RE Calculations'!$C$12:$C$16,"ERROR - Check Input")/12 -> 8.3333333 | I13: Fees | J13: =Inputs!C28 -> 120 | K13: =Inputs!D28 -> per annum | P13: Check | Q13: =Q6*((Q8*((1+Q8)^(Q9*12)))/(((1+Q8)^(Q9*12))-1))+$Q$10*_xlfn.XLOOKUP($R$10,'RE Calculations'!$B$12:$B$16,'RE Calculations'!$C$12:$C$16,"ERROR - Check Input")/12 -> 8.3333333 | W13: Fees | X13: =J13 -> 120 | Y13: =K13 -> per annum
I15: ="Montly Loan Payment (First "&J9&" Years)" -> Montly Loan Payment (First 5 Years) | J15: =J7*J6/12+$J$13*_xlfn.XLOOKUP($K$13,'RE Calculations'!$B$12:$B$16,'RE Calculations'!$C$12:$C$16,"ERROR - Check Input")/12 -> 10 | W15: ="Montly Loan Payment (First "&X9&" Years)" -> Montly Loan Payment (First 5 Years) | X15: =X7*X6/12+$X$13*_xlfn.XLOOKUP($Y$13,'RE Calculations'!$B$12:$B$16,'RE Calculations'!$C$12:$C$16,"ERROR - Check Input")/12 -> 10
I16: ="Montly Loan Payment (After "&J9&" Years)" -> Montly Loan Payment (After 5 Years) | J16: =-PMT(J11,(J12-J9)*12,J6)+$J$13*_xlfn.XLOOKUP($K$13,'RE Calculations'!$B$12:$B$16,'RE Calculations'!$C$12:$C$16,"ERROR - Check Input")/12 -> 10 | W16: ="Montly Loan Payment (After "&X9&" Years)" -> Montly Loan Payment (After 5 Years) | X16: =-PMT(X11,(X12-X9)*12,X6)+$X$13*_xlfn.XLOOKUP($Y$13,'RE Calculations'!$B$12:$B$16,'RE Calculations'!$C$12:$C$16,"ERROR - Check Input")/12 -> 10
